Workbook

Sheet Tổng quan
A1: Tổng quan tiến độ – Project BI Uber NCR
A2: Công cụ tự đánh giá nội bộ theo BIprojectRequirements2026.docx. Không phải thang điểm chính thức của giảng viên.
A4: Cách dùng
A5: • Cập nhật ở sheet Checklist, các cột nền vàng nhạt chữ xanh: Người phụ trách, Tuần, Trạng thái, Ghi chú. Sheet này tự tính lại.
A6: • Ví dụ cách điền: Người phụ trách = A; Tuần = 2; Trạng thái = Đang làm. Nếu đổi tên A/B, hãy sửa cả ô tên ở bảng 'Theo người' bên dưới.
A7: • Ô chữ xanh nền vàng nhạt ở bảng 'Mốc điểm' là ngưỡng do nhóm tự đặt (giả định), có thể chỉnh.
A9: 1. Mốc điểm theo đề và chỉ báo nội bộ
A10: Điều kiện trong đề | B10: Hệ quả theo đề | C10: Chỉ báo nội bộ (số mục Hoàn thành) | D10: Hiện tại | E10: Ngưỡng nhóm đặt | F10: Kết luận
A11: Chỉ dùng kiến thức bài thực hành | B11: Điểm tối đa 5 | C11: Mục độ phức tạp ETL/mô hình/DAX hoàn thành | D11: =COUNTIFS(Checklist!$E$5:$E$200,"Độ phức tạp (trọng số cao)",Checklist!$I$5:$I$200,"Hoàn thành") -> 0 | E11: 8 | F11: =IF(D11>=E11,"Đạt","Chưa đạt") -> Chưa đạt
A12: Chưa đối chiếu kỹ thuật vượt bài thực hành | B12: Điểm tối đa 5 | C12: Mục V (đối chiếu và nêu trong slide) | D12: =COUNTIFS(Checklist!$E$5:$E$200,"Vượt bài thực hành (trần 5)",Checklist!$I$5:$I$200,"Hoàn thành") -> 0 | E12: 2 | F12: =IF(D12>=E12,"Đạt","Chưa đạt") -> Chưa đạt
A13: Chỉ có ETL và dashboard, thiếu khuyến nghị hợp lý | B13: Điểm tối đa 7 | C13: Mục khuyến nghị hoàn thành | D13: =COUNTIFS(Checklist!$E$5:$E$200,"Khuyến nghị (trần 7 nếu thiếu)",Checklist!$I$5:$I$200,"Hoàn thành") -> 0 | E13: 6 | F13: =IF(D13>=E13,"Đạt","Chưa đạt") -> Chưa đạt
A14: Số lượng dashboard (trọng số quan trọng) | B14: Ảnh hưởng điểm | C14: Dashboard hoàn thành | D14: =COUNTIFS(Checklist!$E$5:$E$200,"Số lượng dashboard (trọng số cao)",Checklist!$I$5:$I$200,"Hoàn thành") -> 0 | E14: 6 | F14: =IF(D14>=E14,"Đạt","Chưa đạt") -> Chưa đạt
A15: Dùng học máy, khai phá | B15: Cộng điểm | C15: Mục học máy hoàn thành | D15: =COUNTIFS(Checklist!$E$5:$E$200,"Cộng điểm (học máy)",Checklist!$I$5:$I$200,"Hoàn thành") -> 0 | E15: 1 | F15: =IF(D15>=E15,"Đạt","Chưa đạt") -> Chưa đạt
A16: Nộp đủ sản phẩm | B16: Bắt buộc nộp | C16: Mục nộp bài hoàn thành | D16: =COUNTIFS(Checklist!$E$5:$E$200,"Sản phẩm phải nộp",Checklist!$I$5:$I$200,"Hoàn thành") -> 0 | E16: 6 | F16: =IF(D16>=E16,"Đạt","Chưa đạt") -> Chưa đạt
A17: Chỉ báo chỉ phản ánh tiến độ nhóm đã hoàn thành các mục trong checklist, không phải điểm thực. Ngưỡng là giả định của người lập (đề không nêu số cụ thể).
A19: 2. Tiến độ theo nhóm
A20: Nhóm | B20: Tổng mục | C20: Hoàn thành | D20: Đang làm | E20: Cần xem lại | F20: Chưa làm | G20: % hoàn thành
A21: 0. Tổ chức & dữ liệu | B21: =COUNTIFS(Checklist!$B$5:$B$200,$A21) -> 4 | C21: =COUNTIFS(Checklist!$B$5:$B$200,$A21,Checklist!$I$5:$I$200,"Hoàn thành") -> 0 | D21: =COUNTIFS(Checklist!$B$5:$B$200,$A21,Checklist!$I$5:$I$200,"Đang làm") -> 0 | E21: =COUNTIFS(Checklist!$B$5:$B$200,$A21,Checklist!$I$5:$I$200,"Cần xem lại") -> 0 | F21: =COUNTIFS(Checklist!$B$5:$B$200,$A21,Checklist!$I$5:$I$200,"Chưa làm") -> 4 | G21: =IF(B21=0,0,C21/B21) -> 0
A22: 1. ETL (ngôn ngữ M) | B22: =COUNTIFS(Checklist!$B$5:$B$200,$A22) -> 9 | C22: =COUNTIFS(Checklist!$B$5:$B$200,$A22,Checklist!$I$5:$I$200,"Hoàn thành") -> 0 | D22: =COUNTIFS(Checklist!$B$5:$B$200,$A22,Checklist!$I$5:$I$200,"Đang làm") -> 0 | E22: =COUNTIFS(Checklist!$B$5:$B$200,$A22,Checklist!$I$5:$I$200,"Cần xem lại") -> 0 | F22: =COUNTIFS(Checklist!$B$5:$B$200,$A22,Checklist!$I$5:$I$200,"Chưa làm") -> 9 | G22: =IF(B22=0,0,C22/B22) -> 0
A23: 2. Mô hình dữ liệu | B23: =COUNTIFS(Checklist!$B$5:$B$200,$A23) -> 5 | C23: =COUNTIFS(Checklist!$B$5:$B$200,$A23,Checklist!$I$5:$I$200,"Hoàn thành") -> 0 | D23: =COUNTIFS(Checklist!$B$5:$B$200,$A23,Checklist!$I$5:$I$200,"Đang làm") -> 0 | E23: =COUNTIFS(Checklist!$B$5:$B$200,$A23,Checklist!$I$5:$I$200,"Cần xem lại") -> 0 | F23: =COUNTIFS(Checklist!$B$5:$B$200,$A23,Checklist!$I$5:$I$200,"Chưa làm") -> 5 | G23: =IF(B23=0,0,C23/B23) -> 0
A24: 3. DAX & KPI | B24: =COUNTIFS(Checklist!$B$5:$B$200,$A24) -> 8 | C24: =COUNTIFS(Checklist!$B$5:$B$200,$A24,Checklist!$I$5:$I$200,"Hoàn thành") -> 0 | D24: =COUNTIFS(Checklist!$B$5:$B$200,$A24,Checklist!$I$5:$I$200,"Đang làm") -> 0 | E24: =COUNTIFS(Checklist!$B$5:$B$200,$A24,Checklist!$I$5:$I$200,"Cần xem lại") -> 0 | F24: =COUNTIFS(Checklist!$B$5:$B$200,$A24,Checklist!$I$5:$I$200,"Chưa làm") -> 8 | G24: =IF(B24=0,0,C24/B24) -> 0
A25: 4. Dashboard | B25: =COUNTIFS(Checklist!$B$5:$B$200,$A25) -> 8 | C25: =COUNTIFS(Checklist!$B$5:$B$200,$A25,Checklist!$I$5:$I$200,"Hoàn thành") -> 0 | D25: =COUNTIFS(Checklist!$B$5:$B$200,$A25,Checklist!$I$5:$I$200,"Đang làm") -> 0 | E25: =COUNTIFS(Checklist!$B$5:$B$200,$A25,Checklist!$I$5:$I$200,"Cần xem lại") -> 0 | F25: =COUNTIFS(Checklist!$B$5:$B$200,$A25,Checklist!$I$5:$I$200,"Chưa làm") -> 8 | G25: =IF(B25=0,0,C25/B25) -> 0
A26: 5. Khuyến nghị (Actions) | B26: =COUNTIFS(Checklist!$B$5:$B$200,$A26) -> 8 | C26: =COUNTIFS(Checklist!$B$5:$B$200,$A26,Checklist!$I$5:$I$200,"Hoàn thành") -> 0 | D26: =COUNTIFS(Checklist!$B$5:$B$200,$A26,Checklist!$I$5:$I$200,"Đang làm") -> 0 | E26: =COUNTIFS(Checklist!$B$5:$B$200,$A26,Checklist!$I$5:$I$200,"Cần xem lại") -> 0 | F26: =COUNTIFS(Checklist!$B$5:$B$200,$A26,Checklist!$I$5:$I$200,"Chưa làm") -> 8 | G26: =IF(B26=0,0,C26/B26) -> 0
A27: 6. Học máy / khai phá | B27: =COUNTIFS(Checklist!$B$5:$B$200,$A27) -> 4 | C27: =COUNTIFS(Checklist!$B$5:$B$200,$A27,Checklist!$I$5:$I$200,"Hoàn thành") -> 0 | D27: =COUNTIFS(Checklist!$B$5:$B$200,$A27,Checklist!$I$5:$I$200,"Đang làm") -> 0 | E27: =COUNTIFS(Checklist!$B$5:$B$200,$A27,Checklist!$I$5:$I$200,"Cần xem lại") -> 0 | F27: =COUNTIFS(Checklist!$B$5:$B$200,$A27,Checklist!$I$5:$I$200,"Chưa làm") -> 4 | G27: =IF(B27=0,0,C27/B27) -> 0
A28: 7. Vượt bài thực hành | B28: =COUNTIFS(Checklist!$B$5:$B$200,$A28) -> 2 | C28: =COUNTIFS(Checklist!$B$5:$B$200,$A28,Checklist!$I$5:$I$200,"Hoàn thành") -> 0 | D28: =COUNTIFS(Checklist!$B$5:$B$200,$A28,Checklist!$I$5:$I$200,"Đang làm") -> 0 | E28: =COUNTIFS(Checklist!$B$5:$B$200,$A28,Checklist!$I$5:$I$200,"Cần xem lại") -> 0 | F28: =COUNTIFS(Checklist!$B$5:$B$200,$A28,Checklist!$I$5:$I$200,"Chưa làm") -> 2 | G28: =IF(B28=0,0,C28/B28) -> 0
A29: 8. Sản phẩm nộp & chấm | B29: =COUNTIFS(Checklist!$B$5:$B$200,$A29) -> 6 | C29: =COUNTIFS(Checklist!$B$5:$B$200,$A29,Checklist!$I$5:$I$200,"Hoàn thành") -> 0 | D29: =COUNTIFS(Checklist!$B$5:$B$200,$A29,Checklist!$I$5:$I$200,"Đang làm") -> 0 | E29: =COUNTIFS(Checklist!$B$5:$B$200,$A29,Checklist!$I$5:$I$200,"Cần xem lại") -> 0 | F29: =COUNTIFS(Checklist!$B$5:$B$200,$A29,Checklist!$I$5:$I$200,"Chưa làm") -> 6 | G29: =IF(B29=0,0,C29/B29) -> 0
A30: Tổng | B30: =SUM(B21:B29) -> 54 | C30: =SUM(C21:C29) -> 0 | D30: =SUM(D21:D29) -> 0 | E30: =SUM(E21:E29) -> 0 | F30: =SUM(F21:F29) -> 54 | G30: =IF(B30=0,0,C30/B30) -> 0
A32: 3. Theo người phụ trách
A33: Người phụ trách | B33: Tổng mục | C33: Hoàn thành | D33: Đang làm | E33: Cần xem lại | F33: Chưa làm | G33: % hoàn thành
A34: A | B34: =COUNTIFS(Checklist!$G$5:$G$200,$A34) -> 20 | C34: =COUNTIFS(Checklist!$G$5:$G$200,$A34,Checklist!$I$5:$I$200,"Hoàn thành") -> 0 | D34: =COUNTIFS(Checklist!$G$5:$G$200,$A34,Checklist!$I$5:$I$200,"Đang làm") -> 0 | E34: =COUNTIFS(Checklist!$G$5:$G$200,$A34,Checklist!$I$5:$I$200,"Cần xem lại") -> 0 | F34: =COUNTIFS(Checklist!$G$5:$G$200,$A34,Checklist!$I$5:$I$200,"Chưa làm") -> 20 | G34: =IF(B34=0,0,C34/B34) -> 0
A35: B | B35: =COUNTIFS(Checklist!$G$5:$G$200,$A35) -> 14 | C35: =COUNTIFS(Checklist!$G$5:$G$200,$A35,Checklist!$I$5:$I$200,"Hoàn thành") -> 0 | D35: =COUNTIFS(Checklist!$G$5:$G$200,$A35,Checklist!$I$5:$I$200,"Đang làm") -> 0 | E35: =COUNTIFS(Checklist!$G$5:$G$200,$A35,Checklist!$I$5:$I$200,"Cần xem lại") -> 0 | F35: =COUNTIFS(Checklist!$G$5:$G$200,$A35,Checklist!$I$5:$I$200,"Chưa làm") -> 14 | G35: =IF(B35=0,0,C35/B35) -> 0
A36: Cả hai | B36: =COUNTIFS(Checklist!$G$5:$G$200,$A36) -> 20 | C36: =COUNTIFS(Checklist!$G$5:$G$200,$A36,Checklist!$I$5:$I$200,"Hoàn thành") -> 0 | D36: =COUNTIFS(Checklist!$G$5:$G$200,$A36,Checklist!$I$5:$I$200,"Đang làm") -> 0 | E36: =COUNTIFS(Checklist!$G$5:$G$200,$A36,Checklist!$I$5:$I$200,"Cần xem lại") -> 0 | F36: =COUNTIFS(Checklist!$G$5:$G$200,$A36,Checklist!$I$5:$I$200,"Chưa làm") -> 20 | G36: =IF(B36=0,0,C36/B36) -> 0
A39: 4. Theo tuần dự kiến
A40: Tuần | B40: Số mục dự kiến | C40: Hoàn thành | D40: Đang làm | E40: Cần xem lại | F40: Chưa làm | G40: % hoàn thành
A41: 1 | B41: =COUNTIFS(Checklist!$H$5:$H$200,$A41) -> 5 | C41: =COUNTIFS(Checklist!$H$5:$H$200,$A41,Checklist!$I$5:$I$200,"Hoàn thành") -> 0 | D41: =COUNTIFS(Checklist!$H$5:$H$200,$A41,Checklist!$I$5:$I$200,"Đang làm") -> 0 | E41: =COUNTIFS(Checklist!$H$5:$H$200,$A41,Checklist!$I$5:$I$200,"Cần xem lại") -> 0 | F41: =COUNTIFS(Checklist!$H$5:$H$200,$A41,Checklist!$I$5:$I$200,"Chưa làm") -> 5 | G41: =IF(B41=0,0,C41/B41) -> 0
A42: 2 | B42: =COUNTIFS(Checklist!$H$5:$H$200,$A42) -> 11 | C42: =COUNTIFS(Checklist!$H$5:$H$200,$A42,Checklist!$I$5:$I$200,"Hoàn thành") -> 0 | D42: =COUNTIFS(Checklist!$H$5:$H$200,$A42,Checklist!$I$5:$I$200,"Đang làm") -> 0 | E42: =COUNTIFS(Checklist!$H$5:$H$200,$A42,Checklist!$I$5:$I$200,"Cần xem lại") -> 0 | F42: =COUNTIFS(Checklist!$H$5:$H$200,$A42,Checklist!$I$5:$I$200,"Chưa làm") -> 11 | G42: =IF(B42=0,0,C42/B42) -> 0
A43: 3 | B43: =COUNTIFS(Checklist!$H$5:$H$200,$A43) -> 6 | C43: =COUNTIFS(Checklist!$H$5:$H$200,$A43,Checklist!$I$5:$I$200,"Hoàn thành") -> 0 | D43: =COUNTIFS(Checklist!$H$5:$H$200,$A43,Checklist!$I$5:$I$200,"Đang làm") -> 0 | E43: =COUNTIFS(Checklist!$H$5:$H$200,$A43,Checklist!$I$5:$I$200,"Cần xem lại") -> 0 | F43: =COUNTIFS(Checklist!$H$5:$H$200,$A43,Checklist!$I$5:$I$200,"Chưa làm") -> 6 | G43: =IF(B43=0,0,C43/B43) -> 0
A44: 4 | B44: =COUNTIFS(Checklist!$H$5:$H$200,$A44) -> 5 | C44: =COUNTIFS(Checklist!$H$5:$H$200,$A44,Checklist!$I$5:$I$200,"Hoàn thành") -> 0 | D44: =COUNTIFS(Checklist!$H$5:$H$200,$A44,Checklist!$I$5:$I$200,"Đang làm") -> 0 | E44: =COUNTIFS(Checklist!$H$5:$H$200,$A44,Checklist!$I$5:$I$200,"Cần xem lại") -> 0 | F44: =COUNTIFS(Checklist!$H$5:$H$200,$A44,Checklist!$I$5:$I$200,"Chưa làm") -> 5 | G44: =IF(B44=0,0,C44/B44) -> 0
A45: 5 | B45: =COUNTIFS(Checklist!$H$5:$H$200,$A45) -> 4 | C45: =COUNTIFS(Checklist!$H$5:$H$200,$A45,Checklist!$I$5:$I$200,"Hoàn thành") -> 0 | D45: =COUNTIFS(Checklist!$H$5:$H$200,$A45,Checklist!$I$5:$I$200,"Đang làm") -> 0 | E45: =COUNTIFS(Checklist!$H$5:$H$200,$A45,Checklist!$I$5:$I$200,"Cần xem lại") -> 0 | F45: =COUNTIFS(Checklist!$H$5:$H$200,$A45,Checklist!$I$5:$I$200,"Chưa làm") -> 4 | G45: =IF(B45=0,0,C45/B45) -> 0
A46: 6 | B46: =COUNTIFS(Checklist!$H$5:$H$200,$A46) -> 11 | C46: =COUNTIFS(Checklist!$H$5:$H$200,$A46,Checklist!$I$5:$I$200,"Hoàn thành") -> 0 | D46: =COUNTIFS(Checklist!$H$5:$H$200,$A46,Checklist!$I$5:$I$200,"Đang làm") -> 0 | E46: =COUNTIFS(Checklist!$H$5:$H$200,$A46,Checklist!$I$5:$I$200,"Cần xem lại") -> 0 | F46: =COUNTIFS(Checklist!$H$5:$H$200,$A46,Checklist!$I$5:$I$200,"Chưa làm") -> 11 | G46: =IF(B46=0,0,C46/B46) -> 0
...

Sheet Checklist
A1: Checklist chấm điểm – Project BI Uber NCR
A2: Căn cứ: BIprojectRequirements2026.docx. Cột G, H, I, J có nền vàng nhạt là ô để nhóm cập nhật.
A4: Mã | B4: Nhóm | C4: Tiêu chí | D4: Căn cứ trong đề | E4: Ảnh hưởng điểm | F4: Bằng chứng cần có | G4: Người phụ trách | H4: Tuần (1-8) | I4: Trạng thái | J4: Ghi chú
A5: T01 | B5: 0. Tổ chức & dữ liệu | C5: Xác nhận với giảng viên rằng nhóm 2 người được phép và cách chấm nhóm | D5: Cách triển khai: nhóm >1 người chỉ khi lớp từ 27 sinh viên | E5: Nền tảng / điều kiện | F5: Tin nhắn/email xác nhận của giảng viên | G5: Cả hai | H5: 1 | I5: Chưa làm
A6: T02 | B6: 0. Tổ chức & dữ liệu | C6: Dataset hợp lệ, ghi rõ nguồn (Kaggle, data.world hoặc nguồn phù hợp) | D6: Tập dữ liệu | E6: Nền tảng / điều kiện | F6: Trang nguồn + mô tả dataset trong slide | G6: A | H6: 1 | I6: Chưa làm
A7: T03 | B7: 0. Tổ chức & dữ liệu | C7: Báo cáo profiling và Data Quality Log hoàn chỉnh | D7: Hỗ trợ độ phức tạp ETL | E7: Nền tảng / điều kiện | F7: Log ≥7 vấn đề, mỗi vấn đề có cách xử lý | G7: Cả hai | H7: 1 | I7: Chưa làm
A8: T04 | B8: 0. Tổ chức & dữ liệu | C8: Câu hỏi kinh doanh, từ điển KPI và Decision Log | D8: Báo cáo thể hiện hiểu bài toán; KPI đúng nghiệp vụ | E8: Nền tảng / điều kiện | F8: 3 câu hỏi chính, mỗi KPI có công thức và mẫu số | G8: Cả hai | H8: 1 | I8: Chưa làm
A9: E01 | B9: 1. ETL (ngôn ngữ M) | C9: ETL thực hiện bằng Power Query / ngôn ngữ M | D9: Có ETL bằng ngôn ngữ M | E9: Bắt buộc theo đề | F9: Applied Steps + chụp Advanced Editor | G9: A | H9: 2 | I9: Chưa làm
A10: E02 | B10: 1. ETL (ngôn ngữ M) | C10: Làm sạch: bỏ dấu nháy trong ID, ép kiểu, ghép Date + Time thành DateTime | D10: Độ phức tạp ETL | E10: Độ phức tạp (trọng số cao) | F10: Bước làm sạch trong query Fact_Booking | G10: A | H10: 2 | I10: Chưa làm
A11: E03 | B11: 1. ETL (ngôn ngữ M) | C11: Tạo khoá thay thế cho 1.233 Booking ID bị trùng | D11: Độ phức tạp ETL | E11: Độ phức tạp (trọng số cao) | F11: Cột khóa mới + kiểm tra không trùng | G11: A | H11: 2 | I11: Chưa làm
A12: E04 | B12: 1. ETL (ngôn ngữ M) | C12: Unpivot 3 cột lý do thành Dim_Reason, gán nhóm nguyên nhân bằng bảng ánh xạ | D12: Độ phức tạp ETL | E12: Độ phức tạp (trọng số cao) | F12: Dim_Reason + bảng ánh xạ nhóm | G12: B | H12: 2 | I12: Chưa làm
A13: E05 | B13: 1. ETL (ngôn ngữ M) | C13: Dim_Date và Dim_Time (khung giờ) tạo bằng M | D13: Độ phức tạp ETL | E13: Độ phức tạp (trọng số cao) | F13: Hai bảng chiều thời gian | G13: A | H13: 2 | I13: Chưa làm
A14: E06 | B14: 1. ETL (ngôn ngữ M) | C14: Dim_Location dùng cho điểm đón và điểm trả, phân nhóm khu vực | D14: Độ phức tạp ETL | E14: Độ phức tạp (trọng số cao) | F14: Dim_Location + cột khu vực | G14: B | H14: 2 | I14: Chưa làm
A15: E07 | B15: 1. ETL (ngôn ngữ M) | C15: Cột phái sinh: giá/km, nhóm giá, nhóm quãng đường, cờ giá/km bất thường | D15: Độ phức tạp ETL | E15: Độ phức tạp (trọng số cao) | F15: Cột trong Fact_Booking | G15: A | H15: 3 | I15: Chưa làm
A16: E08 | B16: 1. ETL (ngôn ngữ M) | C16: Ít nhất 1 custom function M (ví dụ phân khung giờ, chuẩn hoá lý do) | D16: Độ phức tạp ETL | E16: Độ phức tạp (trọng số cao) | F16: Hàm M được gọi lại ở ≥2 chỗ | G16: B | H16: 2 | I16: Chưa làm
... A58: S06 | B58: 8. Sản phẩm nộp & chấm | C58: Sẵn sàng theo lịch chấm (thứ tự danh sách lớp, 2-3 tuần cuối) | D58: Thời gian chấm dự án | E58: Sản phẩm phải nộp | F58: Xác nhận lịch với lớp/giảng viên | G58: Cả hai | H58: 8 | I58: Chưa làm
